Workbook
Name tblaccounts: ravenstack_accounts[]
Name tblchurnevents: ravenstack_churn_events[]
Name tblfeatureusage: ravenstack_feature_usage[]
Name tblsubscriptions: ravenstack_subscriptions[]
Name tblsupporttickets: ravenstack_support_tickets[]
Name tblubscriptions: ravenstack_subscriptions[]

Sheet Accounts
A1: account_id | B1: account_name | C1: industry | D1: country | E1: signup_date | F1: referral_source | G1: plan_tier | H1: seats | I1: is_trial | J1: churn_flag
A2: A-2e4581 | B2: Company_0 | C2: EdTech | D2: US | E2: 45581 | F2: partner | G2: Basic | H2: 9 | I2: FALSE | J2: FALSE
A3: A-0a282f | B3: Company_2 | C3: DevTools | D3: US | E3: 45531 | F3: organic | G3: Basic | H3: 1 | I3: FALSE | J3: FALSE
A4: A-1f0ac7 | B4: Company_3 | C4: HealthTech | D4: UK | E4: 45165 | F4: other | G4: Basic | H4: 24 | I4: TRUE | J4: FALSE
A5: A-1b9609 | B5: Company_5 | C5: EdTech | D5: IN | E5: 45211 | F5: ads | G5: Enterprise | H5: 4 | I5: FALSE | J5: FALSE
A6: A-a0ca4e | B6: Company_6 | C6: Cybersecurity | D6: US | E6: 45359 | F6: ads | G6: Pro | H6: 11 | I6: FALSE | J6: FALSE
A7: A-e5d6ab | B7: Company_7 | C7: EdTech | D7: US | E7: 45031 | F7: partner | G7: Pro | H7: 3 | I7: FALSE | J7: FALSE
A8: A-d40bf7 | B8: Company_11 | C8: FinTech | D8: IN | E8: 45604 | F8: organic | G8: Basic | H8: 59 | I8: FALSE | J8: FALSE
A9: A-6c093d | B9: Company_12 | C9: DevTools | D9: US | E9: 45030 | F9: partner | G9: Basic | H9: 7 | I9: TRUE | J9: FALSE
A10: A-462d45 | B10: Company_13 | C10: Cybersecurity | D10: US | E10: 45306 | F10: partner | G10: Enterprise | H10: 11 | I10: TRUE | J10: FALSE
A11: A-956988 | B11: Company_14 | C11: EdTech | D11: UK | E11: 45626 | F11: ads | G11: Enterprise | H11: 1 | I11: FALSE | J11: FALSE
A12: A-ac14bb | B12: Company_15 | C12: FinTech | D12: US | E12: 45177 | F12: partner | G12: Enterprise | H12: 21 | I12: FALSE | J12: FALSE
A13: A-463db0 | B13: Company_16 | C13: HealthTech | D13: US | E13: 45631 | F13: partner | G13: Basic | H13: 15 | I13: FALSE | J13: FALSE
... A501: A-d26ab4 | B501: Company_497 | C501: DevTools | D501: UK | E501: 45603 | F501: organic | G501: Basic | H501: 9 | I501: FALSE | J501: TRUE

Sheet Subscriptions
A1: subscription_id | B1: account_id | C1: start_date | D1: end_date | E1: plan_tier | F1: seats | G1: mrr_amount | H1: arr_amount | I1: is_trial | J1: upgrade_flag | K1: downgrade_flag | L1: churn_flag | M1: billing_frequency | N1: auto_renew_flag
A2: S-8cec59 | B2: A-3c1a3f | C2: 45283 | D2: 45394 | E2: Enterprise | F2: 14 | G2: 2786 | H2: 33432 | I2: FALSE | J2: FALSE | K2: FALSE | L2: TRUE | M2: monthly | N2: TRUE
A3: S-0f6f44 | B3: A-9b9fe9 | C3: 45454 | E3: Pro | F3: 17 | G3: 833 | H3: 9996 | I3: FALSE | J3: FALSE | K3: FALSE | L3: FALSE | M3: monthly | N3: TRUE
A4: S-51c0d1 | B4: A-659280 | C4: 45621 | E4: Enterprise | F4: 62 | G4: 0 | H4: 0 | I4: TRUE | J4: TRUE | K4: FALSE | L4: FALSE | M4: annual | N4: FALSE
A5: S-f81687 | B5: A-e7a1e2 | C5: 45619 | D5: 45639 | E5: Enterprise | F5: 5 | G5: 995 | H5: 11940 | I5: FALSE | J5: FALSE | K5: FALSE | L5: TRUE | M5: monthly | N5: TRUE
A6: S-cff5a2 | B6: A-ba6516 | C6: 45301 | E6: Enterprise | F6: 27 | G6: 5373 | H6: 64476 | I6: FALSE | J6: FALSE | K6: FALSE | L6: FALSE | M6: monthly | N6: TRUE
A7: S-4b9b13 | B7: A-fa2041 | C7: 45517 | E7: Pro | F7: 15 | G7: 735 | H7: 8820 | I7: FALSE | J7: FALSE | K7: FALSE | L7: FALSE | M7: monthly | N7: TRUE
A8: S-dceac6 | B8: A-417d2f | C8: 45290 | E8: Enterprise | F8: 4 | G8: 796 | H8: 9552 | I8: FALSE | J8: FALSE | K8: FALSE | L8: FALSE | M8: annual | N8: TRUE
A9: S-8cad7b | B9: A-5f2961 | C9: 45649 | E9: Basic | F9: 16 | G9: 304 | H9: 3648 | I9: FALSE | J9: FALSE | K9: FALSE | L9: FALSE | M9: annual | N9: TRUE
A10: S-24796e | B10: A-cc8c8f | C10: 45623 | E10: Enterprise | F10: 23 | G10: 4577 | H10: 54924 | I10: FALSE | J10: FALSE | K10: FALSE | L10: FALSE | M10: annual | N10: FALSE
A11: S-d0c344 | B11: A-80eeb6 | C11: 45592 | E11: Pro | F11: 22 | G11: 1078 | H11: 12936 | I11: FALSE | J11: FALSE | K11: FALSE | L11: FALSE | M11: annual | N11: FALSE
A12: S-477506 | B12: A-f03140 | C12: 45328 | E12: Pro | F12: 27 | G12: 1323 | H12: 15876 | I12: FALSE | J12: FALSE | K12: FALSE | L12: FALSE | M12: annual | N12: TRUE
A13: S-79a9e1 | B13: A-3a5ad8 | C13: 45651 | E13: Enterprise | F13: 22 | G13: 0 | H13: 0 | I13: TRUE | J13: FALSE | K13: FALSE | L13: FALSE | M13: annual | N13: TRUE
A14: S-59dc4b | B14: A-f17767 | C14: 45186 | E14: Pro | F14: 26 | G14: 1274 | H14: 15288 | I14: FALSE | J14: TRUE | K14: TRUE | L14: FALSE | M14: monthly | N14: TRUE
A15: S-7acd8b | B15: A-7920cc | C15: 45490 | E15: Basic | F15: 39 | G15: 741 | H15: 8892 | I15: FALSE | J15: FALSE | K15: FALSE | L15: FALSE | M15: annual | N15: TRUE
A16: S-428e9a | B16: A-8ae3fc | C16: 45577 | E16: Enterprise | F16: 88 | G16: 0 | H16: 0 | I16: TRUE | J16: FALSE | K16: FALSE | L16: FALSE | M16: monthly | N16: TRUE
A17: S-486088 | B17: A-0cc442 | C17: 45553 | E17: Pro | F17: 45 | G17: 2205 | H17: 26460 | I17: FALSE | J17: FALSE | K17: FALSE | L17: FALSE | M17: monthly | N17: TRUE
A18: S-13939b | B18: A-86902e | C18: 45128 | D18: 45507 | E18: Pro | F18: 34 | G18: 0 | H18: 0 | I18: TRUE | J18: FALSE | K18: FALSE | L18: TRUE | M18: monthly | N18: TRUE
A19: S-9333c5 | B19: A-ef84cf | C19: 45449 | D19: 45517 | E19: Basic | F19: 8 | G19: 152 | H19: 1824 | I19: FALSE | J19: FALSE | K19: FALSE | L19: TRUE | M19: annual | N19: FALSE
A20: S-37e3ad | B20: A-b30291 | C20: 45407 | E20: Basic | F20: 5 | G20: 95 | H20: 1140 | I20: FALSE | J20: FALSE | K20: FALSE | L20: FALSE | M20: monthly | N20: TRUE
A21: S-b17d04 | B21: A-e19ff6 | C21: 45357 | E21: Pro | F21: 8 | G21: 392 | H21: 4704 | I21: FALSE | J21: FALSE | K21: FALSE | L21: FALSE | M21: monthly | N21: TRUE
A22: S-c27134 | B22: A-dec005 | C22: 45382 | E22: Pro | F22: 21 | G22: 0 | H22: 0 | I22: TRUE | J22: FALSE | K22: FALSE | L22: FALSE | M22: monthly | N22: TRUE
A23: S-3bd427 | B23: A-2e3bad | C23: 45630 | D23: 45653 | E23: Basic | F23: 61 | G23: 1159 | H23: 13908 | I23: FALSE | J23: FALSE | K23: FALSE | L23: TRUE | M23: monthly | N23: TRUE
A24: S-82989b | B24: A-f5641b | C24: 45626 | E24: Basic | F24: 31 | G24: 589 | H24: 7068 | I24: FALSE | J24: FALSE | K24: FALSE | L24: FALSE | M24: monthly | N24: TRUE
A25: S-082b15 | B25: A-aa9511 | C25: 45331 | E25: Enterprise | F25: 97 | G25: 19303 | H25: 231636 | I25: FALSE | J25: FALSE | K25: FALSE | L25: FALSE | M25: annual | N25: TRUE
A26: S-434140 | B26: A-075038 | C26: 45347 | E26: Pro | F26: 17 | G26: 833 | H26: 9996 | I26: FALSE | J26: FALSE | K26: FALSE | L26: FALSE | M26: annual | N26: TRUE
A27: S-c07ede | B27: A-cea1f0 | C27: 45572 | E27: Pro | F27: 8 | G27: 392 | H27: 4704 | I27: FALSE | J27: FALSE | K27: FALSE | L27: FALSE | M27: annual | N27: FALSE
A28: S-287914 | B28: A-a1b80b | C28: 45519 | E28: Pro | F28: 16 | G28: 784 | H28: 9408 | I28: FALSE | J28: FALSE | K28: FALSE | L28: FALSE | M28: annual | N28: TRUE
A29: S-b3bd43 | B29: A-b2225d | C29: 45599 | E29: Pro | F29: 50 | G29: 2450 | H29: 29400 | I29: FALSE | J29: FALSE | K29: FALSE | L29: FALSE | M29: monthly | N29: FALSE
A30: S-4c82da | B30: A-b9eed8 | C30: 45505 | E30: Pro | F30: 11 | G30: 539 | H30: 6468 | I30: FALSE | J30: FALSE | K30: FALSE | L30: FALSE | M30: monthly | N30: FALSE
A31: S-c75159 | B31: A-bcf87c | C31: 45526 | D31: 45563 | E31: Enterprise | F31: 31 | G31: 6169 | H31: 74028 | I31: FALSE | J31: FALSE | K31: FALSE | L31: TRUE | M31: monthly | N31: TRUE
A32: S-b5643b | B32: A-9f9299 | C32: 45454 | E32: Enterprise | F32: 28 | G32: 5572 | H32: 66864 | I32: FALSE | J32: FALSE | K32: FALSE | L32: FALSE | M32: annual | N32: FALSE
A33: S-49a9aa | B33: A-10b8f2 | C33: 45093 | E33: Basic | F33: 51 | G33: 969 | H33: 11628 | I33: FALSE | J33: FALSE | K33: FALSE | L33: FALSE | M33: annual | N33: TRUE
A34: S-2877e6 | B34: A-95b24a | C34: 45471 | E34: Enterprise | F34: 38 | G34: 0 | H34: 0 | I34: TRUE | J34: TRUE | K34: TRUE | L34: FALSE | M34: monthly | N34: TRUE
A35: S-8c10c1 | B35: A-0651a4 | C35: 45651 | E35: Enterprise | F35: 65 | G35: 12935 | H35: 155220 | I35: FALSE | J35: FALSE | K35: FALSE | L35: FALSE | M35: annual | N35: TRUE
A36: S-d7d398 | B36: A-fb186e | C36: 45654 | E36: Enterprise | F36: 29 | G36: 0 | H36: 0 | I36: TRUE | J36: FALSE | K36: FALSE | L36: FALSE | M36: annual | N36: TRUE
A37: S-ddad91 | B37: A-40906c | C37: 45464 | E37: Enterprise | F37: 92 | G37: 0 | H37: 0 | I37: TRUE | J37: FALSE | K37: FALSE | L37: FALSE | M37: annual | N37: FALSE
A38: S-6762fa | B38: A-40a557 | C38: 45334 | E38: Enterprise | F38: 16 | G38: 3184 | H38: 38208 | I38: FALSE | J38: FALSE | K38: FALSE | L38: FALSE | M38: annual | N38: TRUE
A39: S-bb1cf1 | B39: A-3a5ad8 | C39: 45542 | E39: Enterprise | F39: 9 | G39: 0 | H39: 0 | I39: TRUE | J39: TRUE | K39: FALSE | L39: FALSE | M39: monthly | N39: FALSE
A40: S-a805a5 | B40: A-2789e3 | C40: 45553 | E40: Basic | F40: 33 | G40: 627 | H40: 7524 | I40: FALSE | J40: FALSE | K40: FALSE | L40: FALSE | M40: monthly | N40: TRUE
...

Sheet Feature Usage
A1: usage_id | B1: subscription_id | C1: usage_date | D1: feature_name | E1: usage_count | F1: usage_duration_secs | G1: error_count | H1: is_beta_feature
A2: U-1c6c24 | B2: S-0fcf7d | C2: 45134 | D2: feature_20 | E2: 9 | F2: 5004 | G2: 0 | H2: FALSE
A3: U-f07cb8 | B3: S-c25263 | C3: 45145 | D3: feature_5 | E3: 9 | F3: 369 | G3: 0 | H3: FALSE
A4: U-096807 | B4: S-f29e7f | C4: 45267 | D4: feature_3 | E4: 9 | F4: 1458 | G4: 0 | H4: FALSE
A5: U-6b1580 | B5: S-be655e | C5: 45501 | D5: feature_40 | E5: 5 | F5: 2085 | G5: 0 | H5: FALSE
A6: U-720a29 | B6: S-f9b1d0 | C6: 45628 | D6: feature_12 | E6: 12 | F6: 900 | G6: 0 | H6: FALSE
A7: U-c5692d | B7: S-e958ba | C7: 45230 | D7: feature_14 | E7: 11 | F7: 4103 | G7: 0 | H7: FALSE
A8: U-7078db | B8: S-0c9fdd | C8: 45189 | D8: feature_34 | E8: 8 | F8: 2016 | G8: 2 | H8: FALSE
A9: U-a60033 | B9: S-4e4ab7 | C9: 45082 | D9: feature_27 | E9: 10 | F9: 5470 | G9: 0 | H9: FALSE
A10: U-5cd930 | B10: S-a3a1c1 | C10: 45342 | D10: feature_18 | E10: 9 | F10: 5067 | G10: 1 | H10: FALSE
A11: U-ebb375 | B11: S-9e450b | C11: 44966 | D11: feature_28 | E11: 6 | F11: 2778 | G11: 0 | H11: FALSE
A12: U-a7c89a | B12: S-3673f2 | C12: 45529 | D12: feature_36 | E12: 9 | F12: 2061 | G12: 0 | H12: FALSE
A13: U-779058 | B13: S-afed2d | C13: 45233 | D13: feature_35 | E13: 10 | F13: 5200 | G13: 0 | H13: TRUE
... A25001: U-6c82cc | B25001: S-31428b | C25001: 45616 | D25001: feature_28 | E25001: 10 | F25001: 4790 | G25001: 1 | H25001: FALSE

Sheet Support Tickets
A1: ticket_id | B1: account_id | C1: submitted_at | D1: closed_at | E1: resolution_time_hours | F1: priority | G1: first_response_time_minutes | H1: satisfaction_score | I1: escalation_flag
A2: T-0024de | B2: A-712f1c | C2: 45134 | D2: 45135.125 | E2: 27 | F2: high | G2: 74 | I2: FALSE
A3: T-4d04b9 | B3: A-e43bf7 | C3: 45481 | D3: 45482.125 | E3: 27 | F3: urgent | G3: 144 | I3: FALSE
A4: T-d5e12f | B4: A-0f3e88 | C4: 45582 | D4: 45582.792 | E4: 19 | F4: urgent | G4: 93 | H4: 4 | I4: FALSE
A5: T-dfce9a | B5: A-4c56c9 | C5: 45543 | D5: 45544.958 | E5: 47 | F5: medium | G5: 126 | H5: 5 | I5: FALSE
A6: T-c59f77 | B6: A-6f8ad2 | C6: 45626 | D6: 45627.083 | E6: 26 | F6: medium | G6: 8 | I6: FALSE
A7: T-90f06d | B7: A-94c3cd | C7: 45134 | D7: 45134.375 | E7: 9 | F7: medium | G7: 60 | I7: FALSE
A8: T-30b537 | B8: A-2e4581 | C8: 45178 | D8: 45179.125 | E8: 27 | F8: urgent | G8: 64 | H8: 3 | I8: FALSE
A9: T-60242d | B9: A-72799b | C9: 45320 | D9: 45320.5 | E9: 12 | F9: low | G9: 56 | H9: 4 | I9: TRUE
A10: T-7119c9 | B10: A-b179bf | C10: 45165 | D10: 45165.667 | E10: 16 | F10: urgent | G10: 154 | I10: FALSE
A11: T-b0edf2 | B11: A-7cfe77 | C11: 45418 | D11: 45419.167 | E11: 28 | F11: medium | G11: 150 | H11: 3 | I11: FALSE
A12: T-98a84a | B12: A-157070 | C12: 45280 | D12: 45281.75 | E12: 42 | F12: low | G12: 26 | I12: FALSE
A13: T-04457d | B13: A-854864 | C13: 45491 | D13: 45493 | E13: 48 | F13: medium | G13: 140 | H13: 5 | I13: FALSE
A14: T-6bd715 | B14: A-4e0e85 | C14: 45426 | D14: 45428.083 | E14: 50 | F14: medium | G14: 129 | I14: FALSE
A15: T-13f1b8 | B15: A-5b4ebb | C15: 45265 | D15: 45266.083 | E15: 26 | F15: low | G15: 121 | H15: 5 | I15: FALSE
A16: T-a3288b | B16: A-098560 | C16: 45654 | D16: 45656.292 | E16: 55 | F16: low | G16: 26 | H16: 3 | I16: FALSE
A17: T-f8e2c3 | B17: A-40a557 | C17: 45352 | D17: 45354.875 | E17: 69 | F17: high | G17: 60 | I17: FALSE
A18: T-4e7816 | B18: A-05f0e5 | C18: 45568 | D18: 45569.5 | E18: 36 | F18: low | G18: 108 | I18: FALSE
A19: T-0dea8b | B19: A-671f31 | C19: 45315 | D19: 45317.5 | E19: 60 | F19: medium | G19: 45 | H19: 3 | I19: FALSE
A20: T-ca96ba | B20: A-410e86 | C20: 45410 | D20: 45410.125 | E20: 3 | F20: high | G20: 64 | I20: FALSE
A21: T-ac0b69 | B21: A-ac9111 | C21: 45353 | D21: 45353.583 | E21: 14 | F21: low | G21: 86 | I21: FALSE
A22: T-0f1c67 | B22: A-78f02b | C22: 45574 | D22: 45576 | E22: 48 | F22: low | G22: 51 | H22: 4 | I22: FALSE
A23: T-4fb3f2 | B23: A-c62e55 | C23: 44990 | D23: 44992.458 | E23: 59 | F23: medium | G23: 136 | H23: 3 | I23: FALSE
A24: T-2b4423 | B24: A-158f4e | C24: 45267 | D24: 45267.458 | E24: 11 | F24: high | G24: 99 | I24: FALSE
A25: T-b17401 | B25: A-50bb9f | C25: 45343 | D25: 45343.5 | E25: 12 | F25: high | G25: 171 | H25: 3 | I25: FALSE
A26: T-462ece | B26: A-b9f5b1 | C26: 45124 | D26: 45126.125 | E26: 51 | F26: low | G26: 50 | H26: 3 | I26: TRUE
A27: T-066714 | B27: A-b2225d | C27: 45393 | D27: 45394 | E27: 24 | F27: high | G27: 52 | H27: 3 | I27: FALSE
A28: T-8c694d | B28: A-883b7d | C28: 45436 | D28: 45436.625 | E28: 15 | F28: low | G28: 39 | H28: 3 | I28: TRUE
A29: T-804c6c | B29: A-751bd4 | C29: 45594 | D29: 45595.167 | E29: 28 | F29: medium | G29: 49 | H29: 4 | I29: FALSE
A30: T-64b0b8 | B30: A-533452 | C30: 45196 | D30: 45198.333 | E30: 56 | F30: low | G30: 16 | H30: 5 | I30: FALSE
A31: T-bfa749 | B31: A-684255 | C31: 45142 | D31: 45142.042 | E31: 1 | F31: low | G31: 137 | H31: 5 | I31: FALSE
A32: T-3b24c1 | B32: A-0aaf6e | C32: 45452 | D32: 45454.25 | E32: 54 | F32: high | G32: 151 | H32: 3 | I32: FALSE
A33: T-68c8a6 | B33: A-7c4956 | C33: 45558 | D33: 45558.792 | E33: 19 | F33: high | G33: 34 | I33: FALSE
A34: T-bbe374 | B34: A-3ce5b8 | C34: 45306 | D34: 45308.083 | E34: 50 | F34: low | G34: 155 | I34: FALSE
A35: T-bccf63 | B35: A-82d8a6 | C35: 45625 | D35: 45627.917 | E35: 70 | F35: high | G35: 67 | H35: 3 | I35: FALSE
A36: T-98448a | B36: A-462d45 | C36: 45332 | D36: 45332.75 | E36: 18 | F36: high | G36: 99 | H36: 4 | I36: FALSE
A37: T-f68dde | B37: A-118d55 | C37: 45543 | D37: 45543.583 | E37: 14 | F37: medium | G37: 1 | H37: 4 | I37: FALSE
A38: T-5f84c5 | B38: A-1f559b | C38: 45313 | D38: 45315.583 | E38: 62 | F38: high | G38: 28 | H38: 4 | I38: FALSE
A39: T-9bae5a | B39: A-7cfe77 | C39: 45396 | D39: 45396.958 | E39: 23 | F39: urgent | G39: 176 | H39: 5 | I39: FALSE
A40: T-22842d | B40: A-533452 | C40: 45509 | D40: 45509.333 | E40: 8 | F40: high | G40: 66 | H40: 3 | I40: FALSE
...

Sheet Churn Events
A1: churn_event_id | B1: account_id | C1: churn_date | D1: reason_code | E1: refund_amount_usd | F1: preceding_upgrade_flag | G1: preceding_downgrade_flag | H1: is_reactivation | I1: feedback_text
A2: C-816288 | B2: A-c37cab | C2: 45592 | D2: pricing | E2: 4.03 | F2: FALSE | G2: FALSE | H2: FALSE | I2: switched to competitor
A3: C-5a81e7 | B3: A-37f969 | C3: 45468 | D3: support | E3: 96.45 | F3: TRUE | G3: FALSE | H3: FALSE
A4: C-a174be | B4: A-b07346 | C4: 45608 | D4: budget | E4: 0 | F4: FALSE | G4: FALSE | H4: FALSE | I4: missing features
A5: C-accb39 | B5: A-1e50e0 | C5: 45231 | D5: budget | E5: 54.94 | F5: FALSE | G5: FALSE | H5: FALSE | I5: switched to competitor
A6: C-92f889 | B6: A-956988 | C6: 45656 | D6: unknown | E6: 0 | F6: FALSE | G6: TRUE | H6: TRUE | I6: too expensive
A7: C-a8ac26 | B7: A-b20d99 | C7: 45355 | D7: features | E7: 0 | F7: FALSE | G7: FALSE | H7: FALSE | I7: missing features
A8: C-2e2966 | B8: A-526d93 | C8: 45483 | D8: features | E8: 34.4 | F8: TRUE | G8: FALSE | H8: FALSE
A9: C-ee531b | B9: A-751bd4 | C9: 45557 | D9: budget | E9: 0 | F9: FALSE | G9: FALSE | H9: FALSE
A10: C-e6a0f0 | B10: A-ccabf0 | C10: 45596 | D10: features | E10: 0 | F10: FALSE | G10: FALSE | H10: FALSE | I10: too expensive
A11: C-9328ba | B11: A-0a62f5 | C11: 45575 | D11: features | E11: 0 | F11: FALSE | G11: FALSE | H11: FALSE | I11: switched to competitor
A12: C-c89493 | B12: A-3ce5b8 | C12: 45553 | D12: features | E12: 261.49 | F12: FALSE | G12: FALSE | H12: FALSE | I12: too expensive
A13: C-c54ef0 | B13: A-3b5cd1 | C13: 45534 | D13: unknown | E13: 77.87 | F13: FALSE | G13: FALSE | H13: FALSE | I13: missing features
A14: C-bb3556 | B14: A-bcf664 | C14: 45512 | D14: competitor | E14: 0 | F14: FALSE | G14: FALSE | H14: FALSE
A15: C-875dc5 | B15: A-b9f5b1 | C15: 45128 | D15: features | E15: 0 | F15: FALSE | G15: FALSE | H15: FALSE | I15: switched to competitor
A16: C-c8f7b4 | B16: A-0dbdc6 | C16: 45396 | D16: pricing | E16: 175.02 | F16: FALSE | G16: FALSE | H16: FALSE | I16: too expensive
A17: C-865f19 | B17: A-c9bb3e | C17: 45502 | D17: pricing | E17: 0 | F17: FALSE | G17: FALSE | H17: FALSE | I17: switched to competitor
A18: C-102614 | B18: A-96e141 | C18: 45495 | D18: budget | E18: 43.53 | F18: FALSE | G18: FALSE | H18: FALSE | I18: too expensive
A19: C-4ab0e2 | B19: A-e7a1e2 | C19: 45543 | D19: support | E19: 0 | F19: TRUE | G19: FALSE | H19: FALSE | I19: missing features
A20: C-742a59 | B20: A-812c5b | C20: 45423 | D20: support | E20: 11.83 | F20: FALSE | G20: FALSE | H20: FALSE | I20: missing features
A21: C-1f9cf2 | B21: A-1e50e0 | C21: 45408 | D21: pricing | E21: 0 | F21: FALSE | G21: FALSE | H21: FALSE | I21: switched to competitor
A22: C-5d5a64 | B22: A-c70870 | C22: 45639 | D22: competitor | E22: 0 | F22: FALSE | G22: FALSE | H22: FALSE | I22: switched to competitor
A23: C-f81017 | B23: A-271f46 | C23: 45513 | D23: features | E23: 0 | F23: FALSE | G23: FALSE | H23: TRUE | I23: missing features
A24: C-3292be | B24: A-592832 | C24: 45569 | D24: support | E24: 22.66 | F24: FALSE | G24: FALSE | H24: FALSE | I24: switched to competitor
A25: C-e582ea | B25: A-180abf | C25: 45264 | D25: support | E25: 0 | F25: FALSE | G25: FALSE | H25: FALSE
A26: C-100b97 | B26: A-0a282f | C26: 45571 | D26: features | E26: 0 | F26: FALSE | G26: FALSE | H26: FALSE | I26: switched to competitor
A27: C-8843d4 | B27: A-e51ec7 | C27: 45320 | D27: support | E27: 0 | F27: FALSE | G27: FALSE | H27: FALSE | I27: missing features
A28: C-8b3048 | B28: A-034368 | C28: 45533 | D28: features | E28: 0 | F28: TRUE | G28: FALSE | H28: FALSE
A29: C-48f456 | B29: A-8bde0c | C29: 45624 | D29: features | E29: 0 | F29: FALSE | G29: FALSE | H29: FALSE | I29: missing features
A30: C-dcdebc | B30: A-08e34e | C30: 45486 | D30: competitor | E30: 225.18 | F30: FALSE | G30: FALSE | H30: FALSE | I30: switched to competitor
A31: C-8b229b | B31: A-44dc83 | C31: 45625 | D31: unknown | E31: 98.48 | F31: FALSE | G31: TRUE | H31: FALSE | I31: missing features
A32: C-7d13bf | B32: A-78f02b | C32: 45628 | D32: unknown | E32: 0 | F32: FALSE | G32: FALSE | H32: FALSE | I32: missing features
A33: C-78a2bb | B33: A-fce879 | C33: 45629 | D33: features | E33: 0 | F33: TRUE | G33: FALSE | H33: FALSE | I33: switched to competitor
A34: C-935f48 | B34: A-34ea2f | C34: 45570 | D34: unknown | E34: 0 | F34: TRUE | G34: FALSE | H34: FALSE
A35: C-366a49 | B35: A-0baac2 | C35: 45650 | D35: unknown | E35: 68.65 | F35: FALSE | G35: FALSE | H35: FALSE | I35: switched to competitor
A36: C-62e7a3 | B36: A-ac85cd | C36: 45585 | D36: features | E36: 83.94 | F36: FALSE | G36: FALSE | H36: FALSE
A37: C-f3aca2 | B37: A-439b2f | C37: 45614 | D37: features | E37: 0 | F37: FALSE | G37: FALSE | H37: FALSE | I37: switched to competitor
A38: C-3b7c60 | B38: A-0f6450 | C38: 45655 | D38: competitor | E38: 0 | F38: FALSE | G38: FALSE | H38: FALSE | I38: missing features
A39: C-736efa | B39: A-b78bf8 | C39: 45632 | D39: unknown | E39: 0 | F39: FALSE | G39: FALSE | H39: FALSE
A40: C-f6e873 | B40: A-3b5cd1 | C40: 45497 | D40: support | E40: 35.3 | F40: FALSE | G40: FALSE | H40: FALSE | I40: too expensive
...

Sheet Analysis
A1: Customer Retention & Churn Analysis
A2: KPI | B2: Values
A3: Total Customers | B3: =COUNTA(Accounts!A2:A501) -> 500
A4: Churned Customers | B4: =COUNTIF(Accounts!J2:J501,TRUE) -> 110
A5: Active Customers | B5: =B3-B4 -> 390
A6: Churn Rate | B6: =B4/B3 -> 0.22
A7: Trial Customers | B7: =COUNTIF(Accounts!I2:I501,TRUE) -> 97
A8: Average Seats per Customer | B8: =AVERAGE(Accounts!H2:H501) -> 20.56
A9: Total Subscriptions | B9: =COUNTA(Subscriptions!A2:A5001) -> 5000
A10: Active Subscriptions | B10: =COUNTIF(Subscriptions!L2:L5001,FALSE) -> 4514
A11: Churned Subscriptions | B11: =B9-B10 -> 486
A12: Total Monthly Recurring Revenue (MRR) | B12: =SUM(Subscriptions!G2:G5001) -> 11338747
A13: Total ARR | B13: =SUM(Subscriptions!H2:H5001) -> 136064964
A14: Average MRR | B14: =AVERAGE(Subscriptions!G2:G5001) -> 2267.7494
A15: Total Support Tickets | B15: =COUNTA('Support Tickets'!A2:A2001) -> 2000
A16: Average Resolution Time (Hours) | B16: =AVERAGE('Support Tickets'!E2:E2001) -> 35.861
A17: Average First Response Time (Minutes) | B17: =AVERAGE('Support Tickets'!G2:G2001) -> 88.48
A18: Average Satisfaction Score | B18: =AVERAGE('Support Tickets'!H2:H2001) -> 3.9812766
A19: Escalated Tickets | B19: =COUNTIF('Support Tickets'!I2:I2001,TRUE) -> 95
A20: Total Churn Events | B20: =COUNTA('Churn Events'!A2:A601) -> 600
A21: Total Refund Amount | B21: =SUM('Churn Events'!F2:F601) -> 0
A22: Churn Events After Upgrade | B22: =COUNTIF('Churn Events'!G2:G601,TRUE) -> 53
A23: Churn Events After Downgrade | B23: =COUNTIF('Churn Events'!H2:H601,TRUE) -> 61
A24: Churn Events with Reactivation | B24: =COUNTIF('Churn Events'!I2:I601,TRUE) -> 0
A25: Churn Reason | B25: Churn Events | C25: Churn %
A26: pricing | B26: =COUNTIF('Churn Events'!D2:D601,"pricing") -> 91 | C26: =B26/$B$32 -> 0.15166667
A27: support | B27: =COUNTIF('Churn Events'!D2:D601,"support") -> 104 | C27: =B27/$B$32 -> 0.17333333
A28: budget | B28: =COUNTIF('Churn Events'!D2:D601,"budget") -> 104 | C28: =B28/$B$32 -> 0.17333333
A29: unknown | B29: =COUNTIF('Churn Events'!D2:D601,"unknown") -> 95 | C29: =B29/$B$32 -> 0.15833333
A30: features | B30: =COUNTIF('Churn Events'!D2:D601,"features") -> 114 | C30: =B30/$B$32 -> 0.19
A31: competitor | B31: =COUNTIF('Churn Events'!D2:D601,"competitor") -> 92 | C31: =B31/$B$32 -> 0.15333333
A32: Total | B32: =SUM(B26:B31) -> 600 | C32: =SUM(C26:C31) -> 1
A34: Upgrade Before Churn % | B34: =B22/B20 -> 0.088333333
A35: Downgrade Before Churn % | B35: =B23/B20 -> 0.10166667
A37: Churn by Plan | B37: Churned Subscriptions | C37: Total Subscriptions | D37: Churn Rate
A38: Basic | B38: {=SUMPRODUCT(--(TRIM(Subscriptions!E$2:E$5001)=A38),--(Subscriptions!L$2:L$5001=TRUE))} -> 152 | C38: {=SUMPRODUCT(--(TRIM(Subscriptions!E$2:E$5001)=A38))} -> 1602 | D38: =B38/C38 -> 0.094881398
A39: Pro | B39: {=SUMPRODUCT(--(TRIM(Subscriptions!E$2:E$5001)=A39),--(Subscriptions!L$2:L$5001=TRUE))} -> 162 | C39: {=SUMPRODUCT(--(TRIM(Subscriptions!E$2:E$5001)=A39))} -> 1675 | D39: =B39/C39 -> 0.096716418
A40: Enterprise | B40: {=SUMPRODUCT(--(TRIM(Subscriptions!E$2:E$5001)=A40),--(Subscriptions!L$2:L$5001=TRUE))} -> 172 | C40: {=SUMPRODUCT(--(TRIM(Subscriptions!E$2:E$5001)=A40))} -> 1723 | D40: =B40/C40 -> 0.099825885
A41: Total | B41: =SUM(B38:B40) -> 486 | C41: =SUM(C38:C40) -> 5000 | D41: =B41/C41 -> 0.0972
A43: Churn by Trial Status | B43: Total Customers | C43: Churned Customers | D43: Churn Rate
...

Sheet Dashboard
A1: CUSTOMER CHURN ANALYSIS DASHBOARD
A2: Customer, Subscription, Support & Churn Performance Overview
A3: Total Customers | C3: Customer Churn Rate | E3: Total MRR | G3: Total ARR
A4: =Analysis!B456 -> 500 | C4: =Analysis!B459 -> 0.22 | E4: =Analysis!B443 -> 11338747 | G4: =Analysis!B444 -> 136064964
